Workbook

Sheet Alternatif
A1: No | B1: Alternatif (Nama) | C1: C1: Harga (Rupiah) | D1: C2: RAM (GB) | E1: C3: Kamera (MP) | F1: C4: Kapasitas Baterai (mAh) | G1: C5: Layar (Inch) | H1: C6: Memori (GB)
A2: A01 | B2: Samsung Galaxy Z Flip 5 | C2: 16000000 | D2: 8 | E2: 12 | F2: 3700 | G2: 6.7 | H2: 512
A3: A02 | B3: Xiaomi 14 Ultra | C3: 10000000 | D3: 12 | E3: 50 | F3: 5000 | G3: 6.73 | H3: 512
A4: A03 | B4: Poco F6 | C4: 5000000 | D4: 8 | E4: 64 | F4: 5100 | G4: 6.67 | H4: 256
A5: A04 | B5: Samsung Galaxy S24 Ultra | C5: 21999000 | D5: 12 | E5: 200 | F5: 5000 | G5: 6.8 | H5: 512
A6: A05 | B6: Samsung Galaxy S24 | C6: 14999000 | D6: 8 | E6: 50 | F6: 4000 | G6: 6.2 | H6: 256
A7: A06 | B7: Samsung Galaxy Z Fold 5 | C7: 18000000 | D7: 12 | E7: 50 | F7: 4450 | G7: 7.6 | H7: 512
A8: A07 | B8: Samsung Galaxy A54 5G | C8: 5999000 | D8: 8 | E8: 50 | F8: 5050 | G8: 6.4 | H8: 256
A9: A08 | B9: Samsung Galaxy A34 5G | C9: 4999000 | D9: 8 | E9: 48 | F9: 5000 | G9: 6.65 | H9: 256
A10: A09 | B10: Samsung Galaxy A24 | C10: 2899000 | D10: 8 | E10: 50 | F10: 5000 | G10: 6.5 | H10: 128
A11: A10 | B11: Samsung Galaxy A15 5G | C11: 3599000 | D11: 8 | E11: 50 | F11: 5000 | G11: 6.5 | H11: 256
A12: A11 | B12: Xiaomi 14T Pro | C12: 8499000 | D12: 12 | E12: 50 | F12: 5050 | G12: 6.68 | H12: 256
A13: A12 | B13: Xiaomi 14T | C13: 6499000 | D13: 8 | E13: 50 | F13: 5000 | G13: 6.67 | H13: 256
... A51: A50 | B51: Infinix Note 20 | C51: 2699000 | D51: 8 | E51: 64 | F51: 5200 | G51: 6.78 | H51: 256

Sheet AHP
A1: Kriteria
A2: Kode | B2: Nama
A3: C1 | B3: Harga
A4: C2 | B4: RAM
A5: C3 | B5: Kamera
A6: C4 | B6: Baterai
A7: C5 | B7: Layar
A8: C6 | B8: Memori
A10: Matriks Berpasangan
A11: Kriteria | B11: C1 | C11: C2 | D11: C3 | E11: C4 | F11: C5 | G11: C6
A12: C1 | B12: 1 | C12: 2 | D12: 2 | E12: 2 | F12: 3 | G12: 2
A13: C2 | B13: =C13/C12 -> 0.5 | C13: 1 | D13: 2 | E13: 2 | F13: 3 | G13: 2
A14: C3 | B14: =D14/D12 -> 0.5 | C14: =D14/D13 -> 0.5 | D14: 1 | E14: 2 | F14: 3 | G14: 2
A15: C4 | B15: =E15/E12 -> 0.5 | C15: =E15/E13 -> 0.5 | D15: =E15/E14 -> 0.5 | E15: 1 | F15: 3 | G15: 2
A16: C5 | B16: =F16/F12 -> 0.33333333 | C16: =F16/F13 -> 0.33333333 | D16: =F16/F14 -> 0.33333333 | E16: =F16/F15 -> 0.33333333 | F16: 1 | G16: =F16/F17 -> 0.33333333
A17: C6 | B17: =G17/G12 -> 0.5 | C17: =G17/G13 -> 0.5 | D17: =G17/G14 -> 0.5 | E17: =G17/G15 -> 0.5 | F17: 3 | G17: 1
A18: Jumlah | B18: =SUM(B12:B17) -> 3.3333333 | C18: =SUM(C12:C17) -> 4.8333333 | D18: =SUM(D12:D17) -> 6.3333333 | E18: =SUM(E12:E17) -> 7.8333333 | F18: =SUM(F12:F17) -> 16 | G18: =SUM(G12:G17) -> 9.3333333
A20: Normalisasi
A21: Kriteria | B21: C1 | C21: C2 | D21: C3 | E21: C4 | F21: C5 | G21: C6 | H21: Jumlah | I21: Prioritas
A22: C1 | B22: =B12/$B$18 -> 0.3 | C22: =C12/$C$18 -> 0.4137931 | D22: =D12/$D$18 -> 0.31578947 | E22: =E12/$E$18 -> 0.25531915 | F22: =F12/$F$18 -> 0.1875 | G22: =G12/$G$18 -> 0.21428571 | H22: =SUM(B22:G22) -> 1.6866874 | I22: =H22/6 -> 0.28111457
A23: C2 | B23: =B13/$B$18 -> 0.15 | C23: =C13/$C$18 -> 0.20689655 | D23: =D13/$D$18 -> 0.31578947 | E23: =E13/$E$18 -> 0.25531915 | F23: =F13/$F$18 -> 0.1875 | G23: =G13/$G$18 -> 0.21428571 | H23: =SUM(B23:G23) -> 1.3297909 | I23: =H23/6 -> 0.22163181
A24: C3 | B24: =B14/$B$18 -> 0.15 | C24: =C14/$C$18 -> 0.10344828 | D24: =D14/$D$18 -> 0.15789474 | E24: =E14/$E$18 -> 0.25531915 | F24: =F14/$F$18 -> 0.1875 | G24: =G14/$G$18 -> 0.21428571 | H24: =SUM(B24:G24) -> 1.0684479 | I24: =H24/6 -> 0.17807465
A25: C4 | B25: =B15/$B$18 -> 0.15 | C25: =C15/$C$18 -> 0.10344828 | D25: =D15/$D$18 -> 0.078947368 | E25: =E15/$E$18 -> 0.12765957 | F25: =F15/$F$18 -> 0.1875 | G25: =G15/$G$18 -> 0.21428571 | H25: =SUM(B25:G25) -> 0.86184093 | I25: =H25/6 -> 0.14364016
A26: C5 | B26: =B16/$B$18 -> 0.1 | C26: =C16/$C$18 -> 0.068965517 | D26: =D16/$D$18 -> 0.052631579 | E26: =E16/$E$18 -> 0.042553191 | F26: =F16/$F$18 -> 0.0625 | G26: =G16/$G$18 -> 0.035714286 | H26: =SUM(B26:G26) -> 0.36236457 | I26: =H26/6 -> 0.060394096
A27: C6 | B27: =B17/$B$18 -> 0.15 | C27: =C17/$C$18 -> 0.10344828 | D27: =D17/$D$18 -> 0.078947368 | E27: =E17/$E$18 -> 0.063829787 | F27: =F17/$F$18 -> 0.1875 | G27: =G17/$G$18 -> 0.10714286 | H27: =SUM(B27:G27) -> 0.69086829 | I27: =H27/6 -> 0.11514471
A29: Matriks Penjumlahan
A30: Kriteria | B30: C1 | C30: C2 | D30: C3 | E30: C4 | F30: C5 | G30: C6 | H30: Jumlah
A31: C1 | B31: =B12*$I$22 -> 0.28111457 | C31: =C12*$I$23 -> 0.44326363 | D31: =D12*$I$24 -> 0.35614929 | E31: =E12*$I$25 -> 0.28728031 | F31: =F12*$I$26 -> 0.18118229 | G31: =G12*$I$27 -> 0.23028943 | H31: =SUM(B31:G31) -> 1.7792795
A32: C2 | B32: =B13*$I$22 -> 0.14055729 | C32: =C13*$I$23 -> 0.22163181 | D32: =D13*$I$24 -> 0.35614929 | E32: =E13*$I$25 -> 0.28728031 | F32: =F13*$I$26 -> 0.18118229 | G32: =G13*$I$27 -> 0.23028943 | H32: =SUM(B32:G32) -> 1.4170904
A33: C3 | B33: =B14*$I$22 -> 0.14055729 | C33: =C14*$I$23 -> 0.11081591 | D33: =D14*$I$24 -> 0.17807465 | E33: =E14*$I$25 -> 0.28728031 | F33: =F14*$I$26 -> 0.18118229 | G33: =G14*$I$27 -> 0.23028943 | H33: =SUM(B33:G33) -> 1.1281999
A34: C4 | B34: =B15*$I$22 -> 0.14055729 | C34: =C15*$I$23 -> 0.11081591 | D34: =D15*$I$24 -> 0.089037323 | E34: =E15*$I$25 -> 0.14364016 | F34: =F15*$I$26 -> 0.18118229 | G34: =G15*$I$27 -> 0.23028943 | H34: =SUM(B34:G34) -> 0.89552239
A35: C5 | B35: =B16*$I$22 -> 0.093704858 | C35: =C16*$I$23 -> 0.073877272 | D35: =D16*$I$24 -> 0.059358215 | E35: =E16*$I$25 -> 0.047880052 | F35: =F16*$I$26 -> 0.060394096 | G35: =G16*$I$27 -> 0.038381572 | H35: =SUM(B35:G35) -> 0.37359606
A36: C6 | B36: =B17*$I$22 -> 0.14055729 | C36: =C17*$I$23 -> 0.11081591 | D36: =D17*$I$24 -> 0.089037323 | E36: =E17*$I$25 -> 0.071820078 | F36: =F17*$I$26 -> 0.18118229 | G36: =G17*$I$27 -> 0.11514471 | H36: =SUM(B36:G36) -> 0.7085576
A38: Ratio Konsistensi
A39: Kriteria | B39: Jumlah | C39: Prioritas | D39: Hasil
A40: C1 | B40: =H31 -> 1.7792795 | C40: =I22 -> 0.28111457 | D40: =round(B40/C40,10) -> 6.3293749
A41: C2 | B41: =H32 -> 1.4170904 | C41: =I23 -> 0.22163181 | D41: =round(B41/C41,10) -> 6.3938944
A42: C3 | B42: =H33 -> 1.1281999 | C42: =I24 -> 0.17807465 | D42: =round(B42/C42,10) -> 6.3355446
A43: C4 | B43: =H34 -> 0.89552239 | C43: =I25 -> 0.14364016 | D43: =round(B43/C43,10) -> 6.234485
A44: C5 | B44: =H35 -> 0.37359606 | C44: =I26 -> 0.060394096 | D44: =round(B44/C44,10) -> 6.18597
...

Sheet SAW
A1: Kriteria
A2: Kode | B2: Nama | C2: Tipe | D2: Bobot
A3: C1 | B3: Harga | C3: Cost | D3: =AHP!I22 -> 0.28111457
A4: C2 | B4: RAM | C4: Benefit | D4: =AHP!I23 -> 0.22163181
A5: C3 | B5: Kamera | C5: Benefit | D5: =AHP!I24 -> 0.17807465
A6: C4 | B6: Baterai | C6: Benefit | D6: =AHP!I25 -> 0.14364016
A7: C5 | B7: Layar | C7: Benefit | D7: =AHP!I26 -> 0.060394096
A8: C6 | B8: Memori | C8: Benefit | D8: =AHP!I27 -> 0.11514471
A10: Alternatif
A11: Kode | B11: Nama | C11: C1 | D11: C2 | E11: C3 | F11: C4 | G11: C5 | H11: C6
A12: =Alternatif!A2 -> A01 | B12: =Alternatif!B2 -> Samsung Galaxy Z Flip 5 | C12: =Alternatif!C2 -> 16000000 | D12: =Alternatif!D2 -> 8 | E12: =Alternatif!E2 -> 12 | F12: =Alternatif!F2 -> 3700 | G12: =Alternatif!G2 -> 6.7 | H12: =Alternatif!H2 -> 512
A13: =Alternatif!A3 -> A02 | B13: =Alternatif!B3 -> Xiaomi 14 Ultra | C13: =Alternatif!C3 -> 10000000 | D13: =Alternatif!D3 -> 12 | E13: =Alternatif!E3 -> 50 | F13: =Alternatif!F3 -> 5000 | G13: =Alternatif!G3 -> 6.73 | H13: =Alternatif!H3 -> 512
A14: =Alternatif!A4 -> A03 | B14: =Alternatif!B4 -> Poco F6 | C14: =Alternatif!C4 -> 5000000 | D14: =Alternatif!D4 -> 8 | E14: =Alternatif!E4 -> 64 | F14: =Alternatif!F4 -> 5100 | G14: =Alternatif!G4 -> 6.67 | H14: =Alternatif!H4 -> 256
A15: =Alternatif!A5 -> A04 | B15: =Alternatif!B5 -> Samsung Galaxy S24 Ultra | C15: =Alternatif!C5 -> 21999000 | D15: =Alternatif!D5 -> 12 | E15: =Alternatif!E5 -> 200 | F15: =Alternatif!F5 -> 5000 | G15: =Alternatif!G5 -> 6.8 | H15: =Alternatif!H5 -> 512
A16: =Alternatif!A6 -> A05 | B16: =Alternatif!B6 -> Samsung Galaxy S24 | C16: =Alternatif!C6 -> 14999000 | D16: =Alternatif!D6 -> 8 | E16: =Alternatif!E6 -> 50 | F16: =Alternatif!F6 -> 4000 | G16: =Alternatif!G6 -> 6.2 | H16: =Alternatif!H6 -> 256
A17: =Alternatif!A7 -> A06 | B17: =Alternatif!B7 -> Samsung Galaxy Z Fold 5 | C17: =Alternatif!C7 -> 18000000 | D17: =Alternatif!D7 -> 12 | E17: =Alternatif!E7 -> 50 | F17: =Alternatif!F7 -> 4450 | G17: =Alternatif!G7 -> 7.6 | H17: =Alternatif!H7 -> 512
A18: =Alternatif!A8 -> A07 | B18: =Alternatif!B8 -> Samsung Galaxy A54 5G | C18: =Alternatif!C8 -> 5999000 | D18: =Alternatif!D8 -> 8 | E18: =Alternatif!E8 -> 50 | F18: =Alternatif!F8 -> 5050 | G18: =Alternatif!G8 -> 6.4 | H18: =Alternatif!H8 -> 256
A19: =Alternatif!A9 -> A08 | B19: =Alternatif!B9 -> Samsung Galaxy A34 5G | C19: =Alternatif!C9 -> 4999000 | D19: =Alternatif!D9 -> 8 | E19: =Alternatif!E9 -> 48 | F19: =Alternatif!F9 -> 5000 | G19: =Alternatif!G9 -> 6.65 | H19: =Alternatif!H9 -> 256
A20: =Alternatif!A10 -> A09 | B20: =Alternatif!B10 -> Samsung Galaxy A24 | C20: =Alternatif!C10 -> 2899000 | D20: =Alternatif!D10 -> 8 | E20: =Alternatif!E10 -> 50 | F20: =Alternatif!F10 -> 5000 | G20: =Alternatif!G10 -> 6.5 | H20: =Alternatif!H10 -> 128
A21: =Alternatif!A11 -> A10 | B21: =Alternatif!B11 -> Samsung Galaxy A15 5G | C21: =Alternatif!C11 -> 3599000 | D21: =Alternatif!D11 -> 8 | E21: =Alternatif!E11 -> 50 | F21: =Alternatif!F11 -> 5000 | G21: =Alternatif!G11 -> 6.5 | H21: =Alternatif!H11 -> 256
A22: =Alternatif!A12 -> A11 | B22: =Alternatif!B12 -> Xiaomi 14T Pro | C22: =Alternatif!C12 -> 8499000 | D22: =Alternatif!D12 -> 12 | E22: =Alternatif!E12 -> 50 | F22: =Alternatif!F12 -> 5050 | G22: =Alternatif!G12 -> 6.68 | H22: =Alternatif!H12 -> 256
A23: =Alternatif!A13 -> A12 | B23: =Alternatif!B13 -> Xiaomi 14T | C23: =Alternatif!C13 -> 6499000 | D23: =Alternatif!D13 -> 8 | E23: =Alternatif!E13 -> 50 | F23: =Alternatif!F13 -> 5000 | G23: =Alternatif!G13 -> 6.67 | H23: =Alternatif!H13 -> 256
... A61: =Alternatif!A51 -> A50 | B61: =Alternatif!B51 -> Infinix Note 20 | C61: =Alternatif!C51 -> 2699000 | D61: =Alternatif!D51 -> 8 | E61: =Alternatif!E51 -> 64 | F61: =Alternatif!F51 -> 5200 | G61: =Alternatif!G51 -> 6.78 | H61: =Alternatif!H51 -> 256
C63: Normalisasi Matriks Keputusan
C64: =MIN(C12:C61) -> 1399000 | D64: =MAX(D12:D61) -> 16 | E64: =MAX(E12:E61) -> 200 | F64: =MAX(F12:F61) -> 5910 | G64: =MAX(G12:G61) -> 8 | H64: =MAX(H12:H61) -> 512
A66: Normalisasi Alternatif
A67: Kode | B67: Nama | C67: C1 | D67: C2 | E67: C3 | F67: C4 | G67: C5 | H67: C6
A68: =Alternatif!A2 -> A01 | B68: =Alternatif!B2 -> Samsung Galaxy Z Flip 5 | C68: =round($C$64/C12, 10) -> 0.0874375 | D68: =round(D12/$D$64, 10) -> 0.5 | E68: =round(E12/$E$64, 10) -> 0.06 | F68: =round(F12/$F$64, 10) -> 0.62605753 | G68: =round(G12/$G$64, 10) -> 0.8375 | H68: =round(H12/$H$64, 10) -> 1
A69: =Alternatif!A3 -> A02 | B69: =Alternatif!B3 -> Xiaomi 14 Ultra | C69: =round($C$64/C13, 10) -> 0.1399 | D69: =round(D13/$D$64, 10) -> 0.75 | E69: =round(E13/$E$64, 10) -> 0.25 | F69: =round(F13/$F$64, 10) -> 0.84602369 | G69: =round(G13/$G$64, 10) -> 0.84125 | H69: =round(H13/$H$64, 10) -> 1
A70: =Alternatif!A4 -> A03 | B70: =Alternatif!B4 -> Poco F6 | C70: =round($C$64/C14, 10) -> 0.2798 | D70: =round(D14/$D$64, 10) -> 0.5 | E70: =round(E14/$E$64, 10) -> 0.32 | F70: =round(F14/$F$64, 10) -> 0.86294416 | G70: =round(G14/$G$64, 10) -> 0.83375 | H70: =round(H14/$H$64, 10) -> 0.5
A71: =Alternatif!A5 -> A04 | B71: =Alternatif!B5 -> Samsung Galaxy S24 Ultra | C71: =round($C$64/C15, 10) -> 0.0635938 | D71: =round(D15/$D$64, 10) -> 0.75 | E71: =round(E15/$E$64, 10) -> 1 | F71: =round(F15/$F$64, 10) -> 0.84602369 | G71: =round(G15/$G$64, 10) -> 0.85 | H71: =round(H15/$H$64, 10) -> 1
A72: =Alternatif!A6 -> A05 | B72: =Alternatif!B6 -> Samsung Galaxy S24 | C72: =round($C$64/C16, 10) -> 0.093272885 | D72: =round(D16/$D$64, 10) -> 0.5 | E72: =round(E16/$E$64, 10) -> 0.25 | F72: =round(F16/$F$64, 10) -> 0.67681895 | G72: =round(G16/$G$64, 10) -> 0.775 | H72: =round(H16/$H$64, 10) -> 0.5
A73: =Alternatif!A7 -> A06 | B73: =Alternatif!B7 -> Samsung Galaxy Z Fold 5 | C73: =round($C$64/C17, 10) -> 0.077722222 | D73: =round(D17/$D$64, 10) -> 0.75 | E73: =round(E17/$E$64, 10) -> 0.25 | F73: =round(F17/$F$64, 10) -> 0.75296108 | G73: =round(G17/$G$64, 10) -> 0.95 | H73: =round(H17/$H$64, 10) -> 1
A74: =Alternatif!A8 -> A07 | B74: =Alternatif!B8 -> Samsung Galaxy A54 5G | C74: =round($C$64/C18, 10) -> 0.23320553 | D74: =round(D18/$D$64, 10) -> 0.5 | E74: =round(E18/$E$64, 10) -> 0.25 | F74: =round(F18/$F$64, 10) -> 0.85448393 | G74: =round(G18/$G$64, 10) -> 0.8 | H74: =round(H18/$H$64, 10) -> 0.5
A75: =Alternatif!A9 -> A08 | B75: =Alternatif!B9 -> Samsung Galaxy A34 5G | C75: =round($C$64/C19, 10) -> 0.27985597 | D75: =round(D19/$D$64, 10) -> 0.5 | E75: =round(E19/$E$64, 10) -> 0.24 | F75: =round(F19/$F$64, 10) -> 0.84602369 | G75: =round(G19/$G$64, 10) -> 0.83125 | H75: =round(H19/$H$64, 10) -> 0.5
A76: =Alternatif!A10 -> A09 | B76: =Alternatif!B10 -> Samsung Galaxy A24 | C76: =round($C$64/C20, 10) -> 0.4825802 | D76: =round(D20/$D$64, 10) -> 0.5 | E76: =round(E20/$E$64, 10) -> 0.25 | F76: =round(F20/$F$64, 10) -> 0.84602369 | G76: =round(G20/$G$64, 10) -> 0.8125 | H76: =round(H20/$H$64, 10) -> 0.25
A77: =Alternatif!A11 -> A10 | B77: =Alternatif!B11 -> Samsung Galaxy A15 5G | C77: =round($C$64/C21, 10) -> 0.38871909 | D77: =round(D21/$D$64, 10) -> 0.5 | E77: =round(E21/$E$64, 10) -> 0.25 | F77: =round(F21/$F$64, 10) -> 0.84602369 | G77: =round(G21/$G$64, 10) -> 0.8125 | H77: =round(H21/$H$64, 10) -> 0.5
A78: =Alternatif!A12 -> A11 | B78: =Alternatif!B12 -> Xiaomi 14T Pro | C78: =round($C$64/C22, 10) -> 0.1646076 | D78: =round(D22/$D$64, 10) -> 0.75 | E78: =round(E22/$E$64, 10) -> 0.25 | F78: =round(F22/$F$64, 10) -> 0.85448393 | G78: =round(G22/$G$64, 10) -> 0.835 | H78: =round(H22/$H$64, 10) -> 0.5
A79: =Alternatif!A13 -> A12 | B79: =Alternatif!B13 -> Xiaomi 14T | C79: =round($C$64/C23, 10) -> 0.21526389 | D79: =round(D23/$D$64, 10) -> 0.5 | E79: =round(E23/$E$64, 10) -> 0.25 | F79: =round(F23/$F$64, 10) -> 0.84602369 | G79: =round(G23/$G$64, 10) -> 0.83375 | H79: =round(H23/$H$64, 10) -> 0.5
... A117: =Alternatif!A51 -> A50 | B117: =Alternatif!B51 -> Infinix Note 20 | C117: =round($C$64/C61, 10) -> 0.51834013 | D117: =round(D61/$D$64, 10) -> 0.5 | E117: =round(E61/$E$64, 10) -> 0.32 | F117: =round(F61/$F$64, 10) -> 0.87986464 | G117: =round(G61/$G$64, 10) -> 0.8475 | H117: =round(H61/$H$64, 10) -> 0.5
...
